<?xml version="1.0"?>

<robot xmlns:xacro="http://www.ros.org/wiki/xacro" 
    xmlns:sensor="http://playerstage.sourceforge.net/gazebo/xmlschema/#sensor"
    xmlns:controller="http://playerstage.sourceforge.net/gazebo/xmlschema/#controller"
    xmlns:interface="http://playerstage.sourceforge.net/gazebo/xmlschema/#interface"
    name="dfx_ground_robot">

    <link name="base_footprint"/>

        <joint name="base_joint" type="fixed">
            <parent link="base_footprint"/>
            <child link="base_link"/>
            <origin xyz="0.0 0.0 0.045" rpy="0 0 0"/>
        </joint>

        <link name="base_link">
            <visual>
                <!-- <origin rpy="0 0 0" xyz="-0.065 0 0"/> -->
                <origin rpy="0 0 3.1415" xyz="0 0 -0.0225"/>
                <geometry>
                    <mesh filename="package://dfx_ground_robot_description/meshes/body.stl" />
                </geometry>
                <material name="gray">
                <color rgba="0.2 0.2 0.2 1"/>
                </material>
            </visual>
            <collision>
                <origin rpy="0 0 0" xyz="0 0 0"/>
                <geometry>
                    <mesh filename="package://dfx_ground_robot_description/meshes/body.stl"/>
                </geometry>
            </collision>
            <inertial>
                <origin xyz="0.0 0.0 0.0" rpy="0.0 0.0 0.0"/>
                <mass value="3.314"/>
                <inertia ixx="1.0" ixy="0.0" ixz="0.0" iyy="1.0" iyz="0.0" izz="1.0" />
            </inertial>
    </link>

    <joint name="right_front_joint" type="continuous">
        <parent link="base_link"/>
        <child link="right_front_wheel"/>
        <origin xyz="0.11 -0.08 0.0"/>
        <axis xyz="1 0 0" />
        <limit effort="300" velocity="0.1" lower="-3.14" upper="3.14"/>
        <dynamics damping="50" friction="1"/>
    </joint>

    <link name="right_front_wheel">
        <visual>
            <origin rpy="0 0 0" xyz="0 0 0"/>
            <geometry>
                <mesh filename="package://dfx_ground_robot_description/meshes/right_wheel.stl" />
            </geometry>
            <material name="red">
            <color rgba="0.8 0 0 1"/>
            </material>
        </visual>
        <collision>
            <origin rpy="0 0 0" xyz="0 0 0"/>
            <geometry>
                <mesh filename="package://dfx_ground_robot_description/meshes/right_wheel.stl" />
            </geometry>
        </collision>
        <inertial>
            <origin xyz="0.0 0.0 0.0" rpy="0.0 0.0 0.0"/>
            <mass value="3.314"/>
            <inertia ixx="1.0" ixy="0.0" ixz="0.0" iyy="1.0" iyz="0.0" izz="1.0" />
        </inertial>
    </link>


    <joint name="right_rear_joint" type="continuous">
        <parent link="base_link"/>
        <child link="right_rear_wheel"/>
        <origin xyz="-0.11 -0.08 0.0"/>
        <axis xyz="1 0 0" />
        <limit effort="300" velocity="0.1" lower="-3.14" upper="3.14"/>
        <dynamics damping="50" friction="1"/>
    </joint>

    <link name="right_rear_wheel">
        <visual>
            <origin rpy="0 0 0" xyz="0 0 0"/>
            <geometry>
                <mesh filename="package://dfx_ground_robot_description/meshes/right_wheel.stl" />
            </geometry>
            <material name="red">
            <color rgba="1 1 0 1"/>
            </material>
        </visual>
        <collision>
            <origin rpy="0 0 0" xyz="0 0 0"/>
            <geometry>
                <mesh filename="package://dfx_ground_robot_description/meshes/right_wheel.stl" />
            </geometry>
        </collision>
        <inertial>
            <origin xyz="0.0 0.0 0.0" rpy="0.0 0.0 0.0"/>
            <mass value="3.314"/>
            <inertia ixx="1.0" ixy="0.0" ixz="0.0" iyy="1.0" iyz="0.0" izz="1.0" />
        </inertial>
    </link>

    <joint name="left_front_joint" type="continuous">
        <parent link="base_link"/>
        <child link="left_front_wheel"/>
        <origin xyz="0.11 0.08 0.0"/>
        <axis xyz="1 0 0" />
        <limit effort="300" velocity="0.1" lower="-3.14" upper="3.14"/>
        <dynamics damping="50" friction="1"/>
    </joint>

    <link name="left_front_wheel">
        <visual>
            <origin rpy="0 0 0" xyz="0 0 0"/>
            <geometry>
                <mesh filename="package://dfx_ground_robot_description/meshes/left_wheel.stl" />
            </geometry>
            <material name="red">
            <color rgba="1 1 0 1"/>
            </material>
        </visual>
        <collision>
            <origin rpy="0 0 0" xyz="0 0 0"/>
            <geometry>
                <mesh filename="package://dfx_ground_robot_description/meshes/left_wheel.stl" />
            </geometry>
        </collision>
        <inertial>
            <origin xyz="0.0 0.0 0.0" rpy="0.0 0.0 0.0"/>
            <mass value="3.314"/>
            <inertia ixx="1.0" ixy="0.0" ixz="0.0" iyy="1.0" iyz="0.0" izz="1.0" />
        </inertial>
    </link>


    <joint name="left_rear_joint" type="continuous">
        <parent link="base_link"/>
        <child link="left_rear_wheel"/>
        <origin xyz="-0.11 0.08 0.0"/>
        <axis xyz="1 0 0" />
        <limit effort="300" velocity="0.1" lower="-3.14" upper="3.14"/>
        <dynamics damping="50" friction="1"/>
    </joint>

    <link name="left_rear_wheel">
        <visual>
            <origin rpy="0 0 0" xyz="0 0 0"/>
            <geometry>
                <mesh filename="package://dfx_ground_robot_description/meshes/left_wheel.stl" />
            </geometry>
            <material name="red">
            <color rgba="1 1 0 1"/>
            </material>
        </visual>
        <collision>
            <origin rpy="0 0 0" xyz="0 0 0"/>
            <geometry>
                <mesh filename="package://dfx_ground_robot_description/meshes/left_wheel.stl" />
            </geometry>
        </collision>
        <inertial>
            <origin xyz="0.0 0.0 0.0" rpy="0.0 0.0 0.0"/>
            <mass value="3.314"/>
            <inertia ixx="1.0" ixy="0.0" ixz="0.0" iyy="1.0" iyz="0.0" izz="1.0" />
        </inertial>
    </link>

    <joint name="imu_joint" type="fixed">
        <parent link="base_link"/>
        <child link="imu_link"/>
        <origin xyz="0 0 0.035" rpy="0 0 0"/>
    </joint>

    <link name="imu_link"/>

    <!-- <joint name="camera_joint" type="fixed">
        <origin xyz="0.12 0 0.08" rpy="0 0 0"/>
        <parent link="base_link"/>
        <child link="camera_link"/>
    </joint>


    <link name="camera_link">
        <visual>
        <origin xyz="0 0 0" rpy="1.57 0 1.57"/>
        <geometry>
        <mesh filename="package://realsense2_description/meshes/d435.dae" />
        </geometry>
        </visual>
        <collision>
        <origin xyz="0 0 0" rpy="0 0 0"/>
        <geometry>
            <box size="0.012 0.132 0.020"/>
        </geometry>
        </collision>
    </link>  -->

</robot>